<?xml version="1.0"?>
<!-- 机器人的名字 -->
<robot xmlns:xacro="http://www.ros.org/wiki/xacro">
    <!-- driving wheel 驱动轮-->
    <xacro:macro name="driving_wheel_xacro" params="wheel_name joint_xyz">
        <!-- 机器人的身体部分 -->
        <link name="${wheel_name}_link">
            <!-- 部件的外观描述 -->
            <visual>
                <!-- 沿着自己几何中心的偏移和旋转量 -->
                <origin xyz="0.0 0.0 0.0" rpy="0.0 1.57079 0.0"/>
                <!-- 几何形状 -->
                <geometry>
                    <!-- cylinder:圆柱体;radius:半径:0.1m;length:高度:0.12m; -->
                    <cylinder radius="0.085" length="0.04"/>
                    <!-- <cylinder radius="0.055" length="0.052"/> -->
                </geometry>
                <!-- 材质颜色 -->
                <material name="blue">
                    <color rgba="0.5 0.5 1.0 0.8"/>
                </material>
            </visual>
        </link>
        <!-- 关节 关节类型为可转动的-->
        <joint name="${wheel_name}_joint" type="continuous">
            <!-- 将子部件以固定方式连接在父部件上,固定的偏移量参考父部件的坐标 -->
            <!-- 固定位置 -->
            <origin xyz="${joint_xyz}" rpy="0.0 0.0 0.0"/>
            <!-- 父部件 -->
            <parent link="base_link"/>
            <!-- 子部件 -->
            <child link="${wheel_name}_link"/>
            <axis xyz="1 0.0 0.0"/>
        </joint>
    </xacro:macro>
</robot>